Traceback (most recent call last):
  File "C:\Users\herry\Anaconda3\Lib\site-packages\jupyter_cache\executors\utils.py", line 58, in single_nb_execution
    executenb(
  File "C:\Users\herry\Anaconda3\Lib\site-packages\nbclient\client.py", line 1305, in execute
    return NotebookClient(nb=nb, resources=resources, km=km, **kwargs).execute()
           ^^^^^^^^^^^^^^^^^^^^^^^^^^^^^^^^^^^^^^^^^^^^^^^^^^^^^^^^^^^^^^^^^^^^^
  File "C:\Users\herry\Anaconda3\Lib\site-packages\jupyter_core\utils\__init__.py", line 165, in wrapped
    return loop.run_until_complete(inner)
           ^^^^^^^^^^^^^^^^^^^^^^^^^^^^^^
  File "C:\Users\herry\Anaconda3\Lib\asyncio\base_events.py", line 687, in run_until_complete
    return future.result()
           ^^^^^^^^^^^^^^^
  File "C:\Users\herry\Anaconda3\Lib\site-packages\nbclient\client.py", line 705, in async_execute
    await self.async_execute_cell(
  File "C:\Users\herry\Anaconda3\Lib\site-packages\nbclient\client.py", line 1058, in async_execute_cell
    await self._check_raise_for_error(cell, cell_index, exec_reply)
  File "C:\Users\herry\Anaconda3\Lib\site-packages\nbclient\client.py", line 914, in _check_raise_for_error
    raise CellExecutionError.from_cell_and_msg(cell, exec_reply_content)
nbclient.exceptions.CellExecutionError: An error occurred while executing the following cell:
------------------
import plotly.graph_objects as go

fig = go.Figure(data=go.Scatter(x=[1, 2, 3], y=[10, 20, 15], mode='lines+markers'))
fig.write_image("scatter_plot.png")  # LÆ°u áº£nh

------------------


[1;31m---------------------------------------------------------------------------[0m
[1;31mOSError[0m                                   Traceback (most recent call last)
Cell [1;32mIn[1], line 4[0m
[0;32m      1[0m [38;5;28;01mimport[39;00m [38;5;21;01mplotly[39;00m[38;5;21;01m.[39;00m[38;5;21;01mgraph_objects[39;00m [38;5;28;01mas[39;00m [38;5;21;01mgo[39;00m
[0;32m      3[0m fig [38;5;241m=[39m go[38;5;241m.[39mFigure(data[38;5;241m=[39mgo[38;5;241m.[39mScatter(x[38;5;241m=[39m[[38;5;241m1[39m, [38;5;241m2[39m, [38;5;241m3[39m], y[38;5;241m=[39m[[38;5;241m10[39m, [38;5;241m20[39m, [38;5;241m15[39m], mode[38;5;241m=[39m[38;5;124m'[39m[38;5;124mlines+markers[39m[38;5;124m'[39m))
[1;32m----> 4[0m fig[38;5;241m.[39mwrite_image([38;5;124m"[39m[38;5;124mscatter_plot.png[39m[38;5;124m"[39m)

File [1;32m~\anaconda3\Lib\site-packages\plotly\basedatatypes.py:3835[0m, in [0;36mBaseFigure.write_image[1;34m(self, *args, **kwargs)[0m
[0;32m   3775[0m [38;5;250m[39m[38;5;124;03m"""[39;00m
[0;32m   3776[0m [38;5;124;03mConvert a figure to a static image and write it to a file or writeable[39;00m
[0;32m   3777[0m [38;5;124;03mobject[39;00m
[1;32m   (...)[0m
[0;32m   3831[0m [38;5;124;03mNone[39;00m
[0;32m   3832[0m [38;5;124;03m"""[39;00m
[0;32m   3833[0m [38;5;28;01mimport[39;00m [38;5;21;01mplotly[39;00m[38;5;21;01m.[39;00m[38;5;21;01mio[39;00m [38;5;28;01mas[39;00m [38;5;21;01mpio[39;00m
[1;32m-> 3835[0m [38;5;28;01mreturn[39;00m pio[38;5;241m.[39mwrite_image([38;5;28mself[39m, [38;5;241m*[39margs, [38;5;241m*[39m[38;5;241m*[39mkwargs)

File [1;32m~\anaconda3\Lib\site-packages\plotly\io\_kaleido.py:296[0m, in [0;36mwrite_image[1;34m(fig, file, format, scale, width, height, validate, engine)[0m
[0;32m    286[0m         [38;5;28;01mraise[39;00m [38;5;167;01mValueError[39;00m(
[0;32m    287[0m [38;5;250m            [39m[38;5;124;03m"""[39;00m
[0;32m    288[0m [38;5;124;03mThe 'file' argument '{file}' is not a string, pathlib.Path object, or file descriptor.[39;00m
[1;32m   (...)[0m
[0;32m    291[0m             )
[0;32m    292[0m         )
[0;32m    293[0m     [38;5;28;01melse[39;00m:
[0;32m    294[0m         [38;5;66;03m# We previously succeeded in interpreting `file` as a pathlib object.[39;00m
[0;32m    295[0m         [38;5;66;03m# Now we can use `write_bytes()`.[39;00m
[1;32m--> 296[0m         path[38;5;241m.[39mwrite_bytes(img_data)

File [1;32m~\anaconda3\Lib\pathlib.py:1036[0m, in [0;36mPath.write_bytes[1;34m(self, data)[0m
[0;32m   1034[0m [38;5;66;03m# type-check for the buffer interface before truncating the file[39;00m
[0;32m   1035[0m view [38;5;241m=[39m [38;5;28mmemoryview[39m(data)
[1;32m-> 1036[0m [38;5;28;01mwith[39;00m [38;5;28mself[39m[38;5;241m.[39mopen(mode[38;5;241m=[39m[38;5;124m'[39m[38;5;124mwb[39m[38;5;124m'[39m) [38;5;28;01mas[39;00m f:
[0;32m   1037[0m     [38;5;28;01mreturn[39;00m f[38;5;241m.[39mwrite(view)

File [1;32m~\anaconda3\Lib\pathlib.py:1013[0m, in [0;36mPath.open[1;34m(self, mode, buffering, encoding, errors, newline)[0m
[0;32m   1011[0m [38;5;28;01mif[39;00m [38;5;124m"[39m[38;5;124mb[39m[38;5;124m"[39m [38;5;129;01mnot[39;00m [38;5;129;01min[39;00m mode:
[0;32m   1012[0m     encoding [38;5;241m=[39m io[38;5;241m.[39mtext_encoding(encoding)
[1;32m-> 1013[0m [38;5;28;01mreturn[39;00m io[38;5;241m.[39mopen([38;5;28mself[39m, mode, buffering, encoding, errors, newline)

[1;31mOSError[0m: [Errno 22] Invalid argument: 'scatter_plot.png'

