Traceback (most recent call last):
  File "C:\Users\herry\Anaconda3\Lib\site-packages\jupyter_cache\executors\utils.py", line 58, in single_nb_execution
    executenb(
  File "C:\Users\herry\Anaconda3\Lib\site-packages\nbclient\client.py", line 1305, in execute
    return NotebookClient(nb=nb, resources=resources, km=km, **kwargs).execute()
           ^^^^^^^^^^^^^^^^^^^^^^^^^^^^^^^^^^^^^^^^^^^^^^^^^^^^^^^^^^^^^^^^^^^^^
  File "C:\Users\herry\Anaconda3\Lib\site-packages\jupyter_core\utils\__init__.py", line 165, in wrapped
    return loop.run_until_complete(inner)
           ^^^^^^^^^^^^^^^^^^^^^^^^^^^^^^
  File "C:\Users\herry\Anaconda3\Lib\asyncio\base_events.py", line 687, in run_until_complete
    return future.result()
           ^^^^^^^^^^^^^^^
  File "C:\Users\herry\Anaconda3\Lib\site-packages\nbclient\client.py", line 705, in async_execute
    await self.async_execute_cell(
  File "C:\Users\herry\Anaconda3\Lib\site-packages\nbclient\client.py", line 1058, in async_execute_cell
    await self._check_raise_for_error(cell, cell_index, exec_reply)
  File "C:\Users\herry\Anaconda3\Lib\site-packages\nbclient\client.py", line 914, in _check_raise_for_error
    raise CellExecutionError.from_cell_and_msg(cell, exec_reply_content)
nbclient.exceptions.CellExecutionError: An error occurred while executing the following cell:
------------------
sns.barplot(data=df, x="Category", y="Values", hue="Subcategory", palette="viridis")

------------------


[1;31m---------------------------------------------------------------------------[0m
[1;31mNameError[0m                                 Traceback (most recent call last)
Cell [1;32mIn[1], line 1[0m
[1;32m----> 1[0m sns[38;5;241m.[39mbarplot(data[38;5;241m=[39mdf, x[38;5;241m=[39m[38;5;124m"[39m[38;5;124mCategory[39m[38;5;124m"[39m, y[38;5;241m=[39m[38;5;124m"[39m[38;5;124mValues[39m[38;5;124m"[39m, hue[38;5;241m=[39m[38;5;124m"[39m[38;5;124mSubcategory[39m[38;5;124m"[39m, palette[38;5;241m=[39m[38;5;124m"[39m[38;5;124mviridis[39m[38;5;124m"[39m)

[1;31mNameError[0m: name 'sns' is not defined

